<?xml version="1.0" ?>
<robot name="mecanum" xmlns:xacro="http://ros.org/wiki/xacro">
  <!-- EDIT: FIXED: Correct path to mesh files -->
  <!-- <xacro:property name="mesh_path" value="file:///home/wentao/activity_ws/src/simulator/meshes"/> -->
  <xacro:property name="mesh_path" value="package://simulator/meshes"/>
  <!-- <xacro:property name="sim_share" value="package://simulator"/> -->
  
  <material name="black">
    <color rgba="0 0 0 1"/>
  </material>
  
  <link name="imu_link"/>
  
  <joint name="imu_joint" type="fixed">
    <parent link="base_link"/>
    <child link="imu_link"/>
    <origin xyz="0 0 0" rpy="0 0 -1.57"/>
  </joint>
  
  <link name="base_footprint"/>
  
  <joint name="base_footprint_to_base_link" type="fixed">
    <parent link="base_footprint"/>
    <child link="base_link"/>
    <origin xyz="0 0 0.07" rpy="0 0 0"/>
  </joint>
  <link name="base_link">
    <inertial>
      <origin rpy="0 0 0" xyz="7.82634169708696E-05 3.66518389137982E-05 0.0068167426737893"/>
      <mass value="0.080358044299185"/>
      <inertia ixx="9.92047502462735E-05" ixy="3.20099144678921E-08" ixz="1.15869166655817E-05" iyy="0.000292461515602123" iyz="-2.92890751882614E-08" izz="0.000367604260834833"/>
    </inertial>
    <visual>
      <origin rpy="0 0 0" xyz="0 0 0"/>
      <geometry>
        <mesh filename="${mesh_path}/base_link.STL"/>
      </geometry>
      <material name="white">
        <color rgba="1 1 1 1"/>
      </material>
    </visual>
    <collision>
      <origin rpy="0 0 0" xyz="0 0 0"/>
      <geometry>
        <!-- Use simplified collision for better performance -->
        <box size="0.21 0.1347 0.03"/>
      </geometry>
    </collision>
    
    <!-- Visible collision box for debugging -->
    <visual>
      <origin xyz="0 0 0.015" rpy="0 0 0"/>
      <geometry><box size="0.21 0.1347 0.03"/></geometry>
      <material name="green"><color rgba="0.2 0.8 0.2 0.3"/></material>
    </visual>
  </link>
  
  
  <link name="wheel_lf_Link">
    <inertial>
      <origin rpy="0 0 0" xyz="6.23194347770945E-05 -0.00574614971695361 2.98597149463314E-05"/>
      <mass value="0.0378743634664218"/>
      <inertia ixx="3.67678518315829E-06" ixy="-1.42189561270372E-09" ixz="-1.20320324868622E-08" iyy="5.81008995754212E-06" iyz="1.72329758812212E-09" izz="3.67939460898329E-06"/>
    </inertial>
    <visual>
      <origin rpy="0 0 0" xyz="0 0 0"/>
      <geometry>
        <mesh filename="${mesh_path}/wheel_lf_Link.STL"/>
      </geometry>
      <material name="white">
        <color rgba="1 1 1 1"/>
      </material>
    </visual>
    <collision>
      <origin rpy="0 0 0" xyz="0 0 0"/>
      <geometry>
        <cylinder radius="0.0325" length="0.02"/>
      </geometry>
    </collision>
  </link>
  <joint name="wheel_lf_Joint" type="continuous">
    <origin rpy="0 0 0" xyz="0.067052 0.07591 -0.008408"/>  <!-- Raised by 1cm: -0.018408 + 0.01 -->
    <parent link="base_link"/>
    <child link="wheel_lf_Link"/>
    <axis xyz="0 1 0"/>
  </joint>
  
  <link name="wheel_rf_Link">
    <inertial>
      <origin rpy="0 0 0" xyz="6.22118237483121E-05 0.00574626671891662 2.98167804906255E-05"/>
      <mass value="0.0378687944527435"/>
      <inertia ixx="3.67635322071944E-06" ixy="1.49075106320551E-09" ixz="-1.20440562033349E-08" iyy="5.80905053329656E-06" iyz="-1.7316728972649E-09" izz="3.67859542953002E-06"/>
    </inertial>
    <visual>
      <origin rpy="0 0 0" xyz="0 0 0"/>
      <geometry>
        <mesh filename="${mesh_path}/wheel_rf_Link.STL"/>
      </geometry>
      <material name="white">
        <color rgba="1 1 1 1"/>
      </material>
    </visual>
    <collision>
      <origin rpy="0 0 0" xyz="0 0 0"/>
      <geometry>
        <cylinder radius="0.0325" length="0.02"/>
      </geometry>
    </collision>
  </link>
  <joint name="wheel_rf_Joint" type="continuous">
    <origin rpy="0 0 0" xyz="0.067052 -0.07591 -0.008408"/>  <!-- Raised by 1cm -->
    <parent link="base_link"/>
    <child link="wheel_rf_Link"/>
    <axis xyz="0 1 0"/>
  </joint>
  
  <link name="wheel_lb_Link">
    <inertial>
      <origin rpy="0 0 0" xyz="-4.39089176767909E-05 -0.00574629427498616 3.59684108433914E-05"/>
      <mass value="0.0378689402752074"/>
      <inertia ixx="3.67629328541386E-06" ixy="1.48552620491244E-09" ixz="1.20977149812926E-08" iyy="5.80903210056483E-06" iyz="1.72555302795062E-09" izz="3.6786318488588E-06"/>
    </inertial>
    <visual>
      <origin rpy="0 0 0" xyz="0 0 0"/>
      <geometry>
        <mesh filename="${mesh_path}/wheel_lb_Link.STL"/>
      </geometry>
      <material name="white">
        <color rgba="1 1 1 1"/>
      </material>
    </visual>
    <collision>
      <origin rpy="0 0 0" xyz="0 0 0"/>
      <geometry>
        <cylinder radius="0.0325" length="0.02"/>
      </geometry>
    </collision>
  </link>
  <joint name="wheel_lb_Joint" type="continuous">
    <origin rpy="0 0 0" xyz="-0.06764 0.07591 -0.008414"/>  <!-- Raised by 1cm -->
    <parent link="base_link"/>
    <child link="wheel_lb_Link"/>
    <axis xyz="0 1 0"/>
  </joint>
  
  <link name="wheel_rb_Link">
    <inertial>
      <origin rpy="0 0 0" xyz="-6.2256559793028E-05 0.00574614092169209 2.96857054536206E-05"/>
      <mass value="0.0378742388937267"/>
      <inertia ixx="3.67690880733038E-06" ixy="-1.42614754024296E-09" ixz="1.19925568848388E-08" iyy="5.81009054149328E-06" iyz="-1.72488948912739E-09" izz="3.67928241656151E-06"/>
    </inertial>
    <visual>
      <origin rpy="0 0 0" xyz="0 0 0"/>
      <geometry>
        <mesh filename="${mesh_path}/wheel_rb_Link.STL"/>
      </geometry>
      <material name="white">
        <color rgba="1 1 1 1"/>
      </material>
    </visual>
    <collision>
      <origin rpy="0 0 0" xyz="0 0 0"/>
      <geometry>
        <cylinder radius="0.0325" length="0.02"/>
      </geometry>
    </collision>
  </link>
  <joint name="wheel_rb_Joint" type="continuous">
    <origin rpy="0 0 0" xyz="-0.067621 -0.07591 -0.008408"/>  <!-- Raised by 1cm -->
    <parent link="base_link"/>
    <child link="wheel_rb_Link"/>
    <axis xyz="0 1 0"/>
  </joint>


  <link name="depth_cam">
    <inertial>
      <origin rpy="0 0 0" xyz="0.0023402290706885 0.00113784597175737 -0.010212706399263"/>
      <mass value="0.0270474748712619"/>
      <inertia ixx="1.43718505980935E-05" ixy="1.24779390700312E-07" ixz="1.29836475580818E-08" iyy="1.65912768335363E-06" iyz="2.28291474116005E-08" izz="1.45615925671284E-05"/>
    </inertial>
    <visual>
      <origin rpy="0 0 0" xyz="0 0 0"/>
      <geometry>
        <mesh filename="${mesh_path}/cam_Link.STL"/>
      </geometry>
      <material name="white">
        <color rgba="1 1 1 1"/>
      </material>
    </visual>
    <collision>
      <origin rpy="0 0 0" xyz="0 0 0"/>
      <geometry>
        <box size="0.02 0.02 0.01"/>
      </geometry>
    </collision>
  </link>

  <joint name="cam_Joint" type="fixed">
    <origin rpy="0 0 0" xyz="0.061376 -0.00013463 0.051154"/>
    <parent link="base_link"/>
    <child link="depth_cam"/>
    <axis xyz="0 0 0"/>
  </joint>
  
  <link name="lidar_frame">
    <inertial>
      <origin rpy="0 0 0" xyz="8.65086404290248E-05 9.02624664517182E-05 -0.0183546134707293"/>
      <mass value="0.0405423044439003"/>
      <inertia ixx="4.98470777040832E-06" ixy="-1.5407626531037E-07" ixz="2.05182756187779E-09" iyy="5.03926730954594E-06" iyz="1.10062857837226E-08" izz="8.25645669795306E-06"/>
    </inertial>
    <visual>
      <origin rpy="0 0 0" xyz="0 0 0"/>
      <geometry>
        <mesh filename="${mesh_path}/lidar_Link.STL"/>
      </geometry>
      <material name="white">
        <color rgba="1 1 1 1"/>
      </material>
    </visual>
    <collision>
      <origin rpy="0 0 0" xyz="0 0 0"/>
      <geometry>
        <cylinder radius="0.02" length="0.03"/>
      </geometry>
    </collision>
  </link>
  <joint name="lidar_Joint" type="fixed">
    <origin rpy="0 0 0" xyz="-0.012242 -8.533E-05 0.092501"/>
    <parent link="base_link"/>
    <child link="lidar_frame"/>
    <axis xyz="0 0 0"/>
  </joint>

  <!-- depth_cam sensor -->
  <gazebo reference="depth_cam">
    <sensor type="depth" name="depth_camera">
      <update_rate>15</update_rate>
      <camera>
        <horizontal_fov>1.047</horizontal_fov>
        <image>
          <width>640</width><height>480</height><format>R8G8B8</format>
        </image>
        <clip><near>0.05</near><far>8.0</far></clip>
      </camera>
      <plugin name="gazebo_ros_depth_camera" filename="libgazebo_ros_depth_camera.so">
        <ros>
          <remapping>depth/image_raw:=/camera/depth/image_raw</remapping>
          <remapping>camera_info:=/camera/depth/camera_info</remapping>
          <remapping>points:=/camera/depth/points</remapping>
        </ros>
        <output_points>true</output_points>
        <point_cloud_cutoff>0.05</point_cloud_cutoff>
        <frame_name>depth_cam</frame_name>
      </plugin>
    </sensor>
  </gazebo>

  <!-- Planar move plugin for omnidirectional movement -->
  <gazebo>
    <plugin name="gazebo_ros_planar_move" filename="libgazebo_ros_planar_move.so">
      <ros>
        <namespace>/</namespace>
        <remapping>cmd_vel:=controller/cmd_vel</remapping>
        <remapping>odom:=/odom</remapping>
      </ros>
      <update_rate>100</update_rate>
      <publish_odom>true</publish_odom>
      <publish_odom_tf>true</publish_odom_tf>
      <odometry_frame>odom</odometry_frame>
      <robot_base_frame>base_link</robot_base_frame>
      <command_timeout>0.5</command_timeout>
      <odometry_rate>20.0</odometry_rate>
      <covariance_x>0.0001</covariance_x>
      <covariance_y>0.0001</covariance_y>
      <covariance_yaw>0.01</covariance_yaw>
    </plugin>
  </gazebo>

  <!-- High friction for better control -->
  <gazebo reference="wheel_lf_Link">
    <mu1>1.5</mu1><mu2>1.5</mu2>
    <kp>1000000.0</kp><kd>100.0</kd>
    <minDepth>0.001</minDepth>
    <maxVel>0.1</maxVel>
  </gazebo>
  <gazebo reference="wheel_rf_Link">
    <mu1>1.5</mu1><mu2>1.5</mu2>
    <kp>1000000.0</kp><kd>100.0</kd>
    <minDepth>0.001</minDepth>
    <maxVel>0.1</maxVel>
  </gazebo>
  <gazebo reference="wheel_lb_Link">
    <mu1>1.5</mu1><mu2>1.5</mu2>
    <kp>1000000.0</kp><kd>100.0</kd>
    <minDepth>0.001</minDepth>
    <maxVel>0.1</maxVel>
  </gazebo>
  <gazebo reference="wheel_rb_Link">
    <mu1>1.5</mu1><mu2>1.5</mu2>
    <kp>1000000.0</kp><kd>100.0</kd>
    <minDepth>0.001</minDepth>
    <maxVel>0.1</maxVel>
  </gazebo>

</robot>
